<?xml version="1.0"?>
<robot xmlns:xacro="http://www.ros.org/wiki/xacro" name="my_robot">

    <xacro:macro name="box_inertia" params="m w h d">
        <inertial>
            <mass value="${m}"/>
            <inertia ixx="${(m/12) * (h*h + d*d)}" ixy="0.0" ixz="0.0"
                     iyy="${(m/12) * (w*w + d*d)}" iyz="0.0"
                     izz="${(m/12) * (w*w + h*h)}"/>
        </inertial>
    </xacro:macro>

    <xacro:macro name="cylinder_inertia" params="m r h">
        <inertial>
            <mass value="${m}"/>
            <inertia ixx="${(m/12) * (3*r*r + h*h)}" ixy="0.0" ixz="0.0"
                     iyy="${(m/12) * (3*r*r + h*h)}" iyz="0.0"
                     izz="${(m/2) * (r*r)}"/>
        </inertial>
    </xacro:macro>

    <xacro:macro name="sphere_inertia" params="m r">
        <inertial>
            <mass value="${m}"/>
            <inertia ixx="${(2*m/5) * (r*r)}" ixy="0.0" ixz="0.0"
                     iyy="${(2*m/5) * (r*r)}" iyz="0.0"
                     izz="${(2*m/5) * (r*r)}"/>
        </inertial>
    </xacro:macro>

    <gazebo reference="base_link">
        <material>Gazebo/Pink</material>
    </gazebo>
    <gazebo reference="left_wheel_link">
        <material>Gazebo/Black</material>
    </gazebo>
    <gazebo reference="right_wheel_link">
        <material>Gazebo/Black</material>
    </gazebo>
    <gazebo reference="caster_link">
        <material>Gazebo/Green</material>
    </gazebo>
    <gazebo reference="camera_link">
        <material>Gazebo/Red</material>
    </gazebo>

    <link name="base_link">
        <visual>
            <geometry>
                <box size="0.4 0.3 0.1"/>
            </geometry>
            <origin xyz="0 0 0.05" rpy="0 0 0"/>
            <material name="white">
		<color rgba="1.0 1.0 1.0 1.0"/>
            </material>
        </visual>
        <collision>
            <geometry>
                <box size="0.4 0.3 0.1"/>
            </geometry>
            <origin xyz="0 0 0.05" rpy="0 0 0"/>
        </collision>
        <xacro:box_inertia m="5.0" w="0.4" h="0.3" d="0.1"/>
    </link>

    <link name="left_wheel_link">
        <visual>
            <geometry>
                <cylinder radius="0.05" length="0.04"/>
            </geometry>
            <origin xyz="0 0 0" rpy="1.5707 0 0"/>
            <material name="black">
                <color rgba="0.1 0.1 0.1 1.0"/>
            </material>
        </visual>
        <collision>
            <geometry>
                <cylinder radius="0.05" length="0.04"/>
            </geometry>
            <origin xyz="0 0 0" rpy="1.5707 0 0"/>
        </collision>
        <xacro:cylinder_inertia m="0.5" r="0.05" h="0.04"/>
    </link>

    <joint name="left_wheel_joint" type="continuous">
        <parent link="base_link"/>
        <child link="left_wheel_link"/>
        <origin xyz="0.1 0.17 0.0" rpy="0 0 0"/>
        <axis xyz="0 1 0"/>
    </joint>

    <link name="right_wheel_link">
        <visual>
            <geometry>
                <cylinder radius="0.05" length="0.04"/>
            </geometry>
            <origin xyz="0 0 0" rpy="1.5707 0 0"/>
            <material name="black">
                <color rgba="0.1 0.1 0.1 1.0"/>
            </material>
        </visual>
        <collision>
            <geometry>
                <cylinder radius="0.05" length="0.04"/>
            </geometry>
            <origin xyz="0 0 0" rpy="1.5707 0 0"/>
        </collision>
        <xacro:cylinder_inertia m="0.5" r="0.05" h="0.04"/>
    </link>

    <joint name="right_wheel_joint" type="continuous">
        <parent link="base_link"/>
        <child link="right_wheel_link"/>
        <origin xyz="0.1 -0.17 0.0" rpy="0 0 0"/>
        <axis xyz="0 1 0"/>
    </joint>

    <link name="caster_link">
        <visual>
            <geometry>
                <sphere radius="0.03"/>
            </geometry>
            <origin xyz="0 0 0" rpy="0 0 0"/>
            <material name="green">
                <color rgba="0.5 0.5 0.5 1.0"/>
            </material>
        </visual>
        <collision>
            <geometry>
                <sphere radius="0.03"/>
            </geometry>
            <origin xyz="0 0 0" rpy="0 0 0"/>
        </collision>
        <xacro:sphere_inertia m="0.2" r="0.03"/>
    </link>

    <joint name="caster_joint" type="fixed">
        <parent link="base_link"/>
        <child link="caster_link"/>
        <origin xyz="0.3 0 -0.02" rpy="0 0 0"/>
    </joint>

    <link name="camera_link">
        <visual>
            <geometry>
                <box size="0.02 0.05 0.05"/>
            </geometry>
            <material name="red">
                <color rgba="1.0 0.0 0.0 1.0"/>
            </material>
        </visual>
        <collision>
            <geometry>
                <box size="0.02 0.05 0.05"/>
            </geometry>
        </collision>
        <xacro:box_inertia m="0.1" w="0.02" h="0.05" d="0.05"/>
    </link>

    <joint name="camera_joint" type="fixed">
        <parent link="base_link"/>
        <child link="camera_link"/>
        <origin xyz="0.39 0 0.075" rpy="0 0 0"/>
    </joint>

    <gazebo>
        <plugin name="diff_drive_controller" filename="libgazebo_ros_diff_drive.so">
            <ros>
                <namespace>/</namespace>
                <remapping>/cmd_vel:=/cmd_vel</remapping>
                <remapping>/odom:=/odom</remapping>
            </ros>

            <update_rate>100.0</update_rate>
            <left_joint>left_wheel_joint</left_joint>
            <right_joint>right_wheel_joint</right_joint>

            <wheel_separation>0.34</wheel_separation>
            <wheel_diameter>0.10</wheel_diameter>

            <max_wheel_torque>200</max_wheel_torque>
            <max_wheel_acceleration>10.0</max_wheel_acceleration>

            <publish_odom>true</publish_odom>
            <publish_odom_tf>true</publish_odom_tf>
            <publish_wheel_tf>true</publish_wheel_tf>

            <odometry_frame>odom</odometry_frame>
            <robot_base_frame>base_link</robot_base_frame>
        </plugin>
    </gazebo>

    <gazebo reference="camera_link">
        <sensor type="camera" name="camera">
            <update_rate>30.0</update_rate>
            <camera name="head">
                <horizontal_fov>1.3962634</horizontal_fov>
                <image>
                    <width>800</width>
                    <height>800</height>
                    <format>R8G8B8</format>
                </image>
                <clip>
                    <near>0.02</near>
                    <far>300</far>
                </clip>
            </camera>
            <plugin name="camera_controller" filename="libgazebo_ros_camera.so">
                <ros>
                    <namespace>/</namespace>
                    <remapping>image_raw:=/camera/image_raw</remapping>
                    <remapping>camera_info:=/camera/camera_info</remapping>
                </ros>
                
                <frame_name>camera_link</frame_name>
                <hack_baseline>0.07</hack_baseline>
            </plugin>
        </sensor>
    </gazebo>

</robot>
